<?xml version="1.0"?>
<robot xmlns:xacro="http://www.ros.org/wiki/xacro">

    <link name="arm_link_1">
        <inertial>
            <origin
                xyz="6.304E-07 -0.0012397 0.17667"
                rpy="0 0 0" />
            <mass
                value="0.092448" />
            <inertia
                ixx="0.0003068"
                ixy="-1.5661E-12"
                ixz="1.1831E-12"
                iyy="0.00030817"
                iyz="-8.9565E-07"
                izz="8.6845E-06" />
        </inertial>

        <visual>
            <origin
                xyz="0 0 0"
                rpy="0 0 0" />
            <geometry>
                <mesh
                    filename="package://vx01_description/meshes/drone/arm_link_1.STL" />
            </geometry>
            <material
                name="">
                <color
                    rgba="0.25098 0.25098 0.25098 1" />
            </material>
        </visual>

        <collision>
            <origin
                xyz="0 0 0"
                rpy="0 0 0" />
            <geometry>
                <mesh
                    filename="package://vx01_description/meshes/drone/arm_link_1.STL" />
            </geometry>
        </collision>
    </link>

    <joint name="arm_joint_1" type="revolute">
        <origin
            xyz="0.02791 0.027022 0.115"
            rpy="-1.5708 0 -0.82476" />
        <parent
            link="base_link" />
        <child
            link="arm_link_1" />
        <axis
            xyz="0 0 -1" />
        <limit
            lower="-1.57"
            upper="1.57"
            effort="0"
            velocity="0" />
    </joint>

    <link name="prop_link_1">
        <inertial>
            <origin
                xyz="-1.1458E-07 -5.7657E-08 -0.002497"
                rpy="0 0 0" />
            <mass
                value="0.0055592" />
            <inertia
                ixx="6.7033E-06"
                ixy="-9.2254E-06"
                ixz="3.8175E-13"
                iyy="1.3165E-05"
                iyz="1.2749E-12"
                izz="1.983E-05" />
        </inertial>

        <visual>
            <origin
                xyz="0 0 0"
                rpy="0 0 0" />
            <geometry>
                <mesh
                    filename="package://vx01_description/meshes/drone/prop_link_1.STL" />
            </geometry>
            <material
                name="">
                <color
                    rgba="0.29412 0.29412 0.29412 1" />
            </material>
        </visual>

        <collision>
            <origin
                xyz="0 0 0"
                rpy="0 0 0" />
            <geometry>
                <mesh
                    filename="package://vx01_description/meshes/drone/prop_link_1.STL" />
            </geometry>
        </collision>
    </link>

    <joint name="prop_1" type="continuous">
        <origin
            xyz="0 -0.037248 0.2725"
            rpy="1.5708 0 0" />
        <parent
            link="arm_link_1" />
        <child
            link="prop_link_1" />
        <axis
            xyz="0 0 1" />
    </joint>

</robot>