<?xml version="1.0"?>
<robot xmlns:xacro="http://www.ros.org/wiki/xacro">

    <link name="arm_link_2">
        <inertial>
            <origin
                xyz="-6.6934E-10 0.00071305 0.16092"
                rpy="0 0 0" />
            <mass
                value="0.079293" />
            <inertia
                ixx="0.00030593"
                ixy="-1.7223E-12"
                ixz="6.4662E-13"
                iyy="0.00030691"
                iyz="-8.9862E-07"
                izz="7.8455E-06" />
        </inertial>

        <visual>
            <origin
                xyz="0 0 0"
                rpy="0 0 0" />
            <geometry>
                <mesh
                    filename="package://vx01_description/meshes/drone/arm_link_2.STL" />
            </geometry>
            <material
                name="">
                <color
                    rgba="0.25098 0.25098 0.25098 1" />
            </material>
        </visual>

        <collision>
            <origin
                xyz="0 0 0"
                rpy="0 0 0" />
            <geometry>
                <mesh
                    filename="package://vx01_description/meshes/drone/arm_link_2.STL" />
            </geometry>
        </collision>
    </link>

    <joint name="arm_joint2" type="revolute">
        <origin
            xyz="-0.0305865326107599 0.0270219698219533 0.115"
            rpy="-1.5707963267949 0 0.824761604187581" />
        <parent
            link="base_link" />
        <child
            link="arm_link_2" />
        <axis
            xyz="0 0 -1" />
        <limit
            lower="-1.57"
            upper="1.57"
            effort="1.5"
            velocity="3.14" />
    </joint>

    <link name="motor_link_2">
        <inertial>
            <origin
                xyz="4.4318E-06 -0.01301 -0.00086646"
                rpy="0 0 0" />
            <mass
                value="0.013155" />
            <inertia
                ixx="8.6253E-07"
                ixy="-7.3924E-14"
                ixz="-1.2379E-13"
                iyy="1.2626E-06"
                iyz="2.9714E-09"
                izz="8.3905E-07" />
        </inertial>

        <visual>
            <origin
                xyz="0 0 0"
                rpy="0 0 0" />
            <geometry>
                <mesh
                    filename="package://vx01_description/meshes/drone/motor_link_2.STL" />
            </geometry>
            <material
                name="">
                <color
                    rgba="0.95686 0.95686 0.95686 1" />
            </material>
        </visual>

        <collision>
            <origin
                xyz="0 0 0"
                rpy="0 0 0" />
            <geometry>
                <mesh
                    filename="package://vx01_description/meshes/drone/motor_link_2.STL" />
            </geometry>
        </collision>
    </link>

    <joint name="motor_2" type="fixed">
        <origin
            xyz="0 0 0.2725"
            rpy="0 0 0" />
        <parent
            link="arm_link_2" />
        <child
            link="motor_link_2" />
        <axis
            xyz="0 0 0" />
    </joint>

    <link name="prop_link_2">
        <inertial>
            <origin
                xyz="4.0947E-08 4.5855E-08 -0.0054488"
                rpy="0 0 0" />
            <mass
                value="0.0055592" />
            <inertia
                ixx="6.7032E-06"
                ixy="-9.2253E-06"
                ixz="-6.229E-13"
                iyy="1.3165E-05"
                iyz="4.5793E-13"
                izz="1.983E-05" />
        </inertial>

        <visual>
            <origin
                xyz="0 0 0"
                rpy="0 0 0" />
            <geometry>
                <mesh
                    filename="package://vx01_description/meshes/drone/prop_link_2.STL" />
            </geometry>
            <material
                name="">
                <color
                    rgba="0.29412 0.29412 0.29412 1" />
            </material>
        </visual>

        <collision>
            <origin
                xyz="0 0 0"
                rpy="0 0 0" />
            <geometry>
                <mesh
                    filename="package://vx01_description/meshes/drone/prop_link_2.STL" />
            </geometry>
        </collision>
    </link>

    <joint name="prop_2" type="continuous">
        <origin
            xyz="0 -0.0402 0"
            rpy="1.5708 0 0" />
        <parent
            link="motor_link_2" />
        <child
            link="prop_link_2" />
        <axis
            xyz="0 0 1" />
    </joint>

</robot>