<?xml version="1.0"?>
<robot xmlns:xacro="http://www.ros.org/wiki/xacro">

    <link name="coxa_link_1">
        <inertial>
            <origin
                xyz="0.0297 -5.4594E-05 -0.026608"
                rpy="0 0 0" />
            <mass
                value="0.029307" />
            <inertia
                ixx="1.3314E-05"
                ixy="-3.1849E-07"
                ixz="-3.1873E-07"
                iyy="1.0662E-05"
                iyz="-1.7684E-20"
                izz="1.0686E-05" />
        </inertial>

        <visual>
            <origin
                xyz="0 0 0"
                rpy="0 0 0" />
            <geometry>
                <mesh
                    filename="package://vx01_description/meshes/hexapod/coxa_link_1.STL" />
            </geometry>
            <material
                name="">
                <color
                    rgba="0.25098 0.25098 0.25098 1" />
            </material>
        </visual>

        <collision>
            <origin
                xyz="0 0 0"
                rpy="0 0 0" />
            <geometry>
                <mesh
                    filename="package://vx01_description/meshes/hexapod/coxa_link_1.STL" />
            </geometry>
        </collision>
    </link>

    <joint name="coxa_leg1_joint" type="revolute">
        <origin
            xyz="0.1215 -0.062844 0.0696"
            rpy="0 0 -0.7854" />
        <parent
            link="base_link" />
        <child
            link="coxa_link_1" />
        <axis
            xyz="0 0 -1" />
        <limit
            lower="-0.78"
            upper="0.78"
            effort="1.5"
            velocity="3.14" />
    </joint>

    <link name="femur_link_1">
        <inertial>
            <origin
                xyz="0.026111 -0.00084611 -0.028374"
                rpy="0 0 0" />
            <mass
                value="0.050023" />
            <inertia
                ixx="1.1196E-05"
                ixy="6.6735E-07"
                ixz="2.0759E-07"
                iyy="1.5254E-05"
                iyz="-1.2674E-07"
                izz="1.152E-05" />
        </inertial>

        <visual>
            <origin
                xyz="0 0 0"
                rpy="0 0 0" />
            <geometry>
                <mesh
                    filename="package://vx01_description/meshes/hexapod/femur_link_1.STL" />
            </geometry>
            <material
                name="">
                <color
                    rgba="1 1 1 1" />
            </material>
        </visual>

        <collision>
            <origin
                xyz="0 0 0"
                rpy="0 0 0" />
            <geometry>
                <mesh
                    filename="package://vx01_description/meshes/hexapod/femur_link_1.STL" />
            </geometry>
        </collision>
    </link>

    <joint name="femur_leg1_joint" type="revolute">
        <origin
            xyz="0.060781 -0.0273 -0.0273"
            rpy="1.5708 0 0" />
        <parent
            link="coxa_link_1" />
        <child
            link="femur_link_1" />
        <axis
            xyz="0 0 -1" />
        <limit
            lower="-0.78"
            upper="0.10"
            effort="1.5"
            velocity="3.14" />
    </joint>

    <link name="tibia_link_1">
        <inertial>
            <origin
                xyz="0.038765 -0.021212 -0.028549"
                rpy="0 0 0" />
            <mass
                value="0.070022" />
            <inertia
                ixx="3.193E-05"
                ixy="7.4621E-06"
                ixz="3.289E-09"
                iyy="2.5569E-05"
                iyz="-3.0919E-10"
                izz="3.3073E-05" />
        </inertial>

        <visual>
            <origin
                xyz="0 0 0"
                rpy="0 0 0" />
            <geometry>
                <mesh
                    filename="package://vx01_description/meshes/hexapod/tibia_link_1.STL" />
            </geometry>
            <material
                name="">
                <color
                    rgba="0.79216 0.81961 0.93333 1" />
            </material>
        </visual>

        <collision>
            <origin
                xyz="0 0 0"
                rpy="0 0 0" />
            <geometry>
                <mesh
                    filename="package://vx01_description/meshes/hexapod/tibia_link_1.STL" />
            </geometry>
        </collision>
    </link>

    <joint name="tibia_leg1_joint" type="revolute">
        <origin
            xyz="0.072592 -0.013442 -0.0018"
            rpy="0 0 -0.7854" />
        <parent
            link="femur_link_1" />
        <child
            link="tibia_link_1" />
        <axis
            xyz="0 0 -1" />
        <limit
            lower="-0.78"
            upper="0.10"
            effort="1.5"
            velocity="3.14" />
    </joint>

</robot>