<?xml version="1.0"?>
<robot xmlns:xacro="http://www.ros.org/wiki/xacro">

    <link name="coxa_link_0">
        <inertial>
            <origin
                xyz="0.0297 -5.4594E-05 -0.026608"
                rpy="0 0 0" />
            <mass
                value="0.029307" />
            <inertia
                ixx="1.3314E-05"
                ixy="-3.1849E-07"
                ixz="-3.1873E-07"
                iyy="1.0662E-05"
                iyz="-1.7669E-20"
                izz="1.0686E-05" />
        </inertial>

        <visual>
            <origin
                xyz="0 0 0"
                rpy="0 0 0" />
            <geometry>
                <mesh
                    filename="package://vx01_description/meshes/hexapod/coxa_link_0.STL" />
            </geometry>
            <material
                name="">
                <color
                    rgba="0.25098 0.25098 0.25098 1" />
            </material>
        </visual>

        <collision>
            <origin
                xyz="0 0 0"
                rpy="0 0 0" />
            <geometry>
                <mesh
                    filename="package://vx01_description/meshes/hexapod/coxa_link_0.STL" />
            </geometry>
        </collision>
    </link>

    <joint name="coxa_leg0_joint" type="revolute">
        <origin
            xyz="-0.0013383 -0.10566 0.0696"
            rpy="0 0 -1.5708" />
        <parent
            link="base_link" />
        <child
            link="coxa_link_0" />
        <axis
            xyz="0 0 -1" />
        <limit
            lower="-1.57"
            upper="1.57"
            effort="0"
            velocity="0" />
    </joint>

    <link name="femur_link_0">
        <inertial>
            <origin
                xyz="0.026007 0.0024786 -0.028374"
                rpy="0 0 0" />
            <mass
                value="0.050023" />
            <inertia
                ixx="1.1093E-05"
                ixy="1.3432E-07"
                ixz="2.2201E-07"
                iyy="1.5357E-05"
                iyz="-9.9336E-08"
                izz="1.152E-05" />
        </inertial>

        <visual>
            <origin
                xyz="0 0 0"
                rpy="0 0 0" />
            <geometry>
                <mesh
                    filename="package://vx01_description/meshes/hexapod/femur_link_0.STL" />
            </geometry>
            <material
                name="">
                <color
                    rgba="0.79216 0.81961 0.93333 1" />
            </material>
        </visual>

        <collision>
            <origin
                xyz="0 0 0"
                rpy="0 0 0" />
            <geometry>
                <mesh
                filename="package://vx01_description/meshes/hexapod/femur_link_0.STL" />
            </geometry>
        </collision>
    </link>

    <joint name="femur_leg0_joint" type="revolute">
        <origin
            xyz="0.060781 -0.0273 -0.0273"
            rpy="1.5708 0.12741 0" />
        <parent
            link="coxa_link_0" />
        <child
            link="femur_link_0" />
        <axis
            xyz="0 0 -1" />
        <limit
            lower="-1.57"
            upper="1.57"
            effort="0"
            velocity="0" />
    </joint>

    <link name="tibia_link_0">
        <inertial>
            <origin
                xyz="0.038765 -0.021212 -0.028549"
                rpy="0 0 0" />
            <mass
                value="0.070022" />
            <inertia
                ixx="3.193E-05"
                ixy="7.4621E-06"
                ixz="3.289E-09"
                iyy="2.5569E-05"
                iyz="-3.0941E-10"
                izz="3.3073E-05" />
        </inertial>

        <visual>
            <origin
                xyz="0 0 0"
                rpy="0 0 0" />
            <geometry>
                <mesh
                    filename="package://vx01_description/meshes/hexapod/tibia_link_0.STL" />
            </geometry>
            <material
                name="">
                <color
                    rgba="0.79216 0.81961 0.93333 1" />
            </material>
        </visual>

        <collision>
            <origin
                xyz="0 0 0"
                rpy="0 0 0" />
            <geometry>
                <mesh
                    filename="package://vx01_description/meshes/hexapod/tibia_link_0.STL" />
            </geometry>
        </collision>
    </link>

    <joint name="tibia_leg0_joint" type="revolute">
        <origin
            xyz="0.073712 -0.0041095 -0.0018"
            rpy="0 0 -0.65799" />
        <parent
            link="femur_link_0" />
        <child
            link="tibia_link_0" />
        <axis
            xyz="0 0 -1" />
        <limit
            lower="-1.57"
            upper="1.57"
            effort="0"
            velocity="0" />
    </joint>

</robot>